## 认识异常

程序过程中可能有很多出错的情况，出错的原因可能是多方面的，有的是不可控的内部原因，比如内存不够了、磁盘满了，有的是不可控的外部原因，比如网络连接有问题，更多的可能是程序的编程错误，比如引用变量未初始化就直接调用实例方法。

### 常见的异常
#### NullPointerException (空指针异常)
我们先看一段代码：
```java  
package com.example;
public class ExceptionTest {
    public static void main(String[] args) {
        String s = null;
        s.indexOf("a");
        System.out.println("end");
    }
}
```
变量s没有初始化就调用其实例方法indexOf，运行，屏幕输出为：  
>Exception in thread "main" java.lang.NullPointerException
    at ExceptionTest.main(ExceptionTest.java:5)

输出是告诉我们：在ExceptionTest类的main函数中，代码第5行，出现了空指针异常(java.lang.NullPointerException)。     
**原因：**  
当执行s.indexOf("a")的时候，Java系统发现s的值为null，没有办法继续执行了，这时就启用异常处理机制，首先创建一个异常对象，这里是类NullPointerException的对象，然后查找看谁能处理这个异常，在示例代码中，没有代码能处理这个异常，Java就启用默认处理机制，那就是打印异常栈信息到屏幕，并退出程序。

#### NumberFormatException(数字格式异常)
```java
package com.example;
public class ExceptionTest {
  public static void main(String[] arg)  {
      int result= Integer.parseInt("ab3");
      System.out.println("result == " + result);
  }
}
```
>Exception in thread "main" java.lang.NumberFormatException: For input string: "ab3"
	at java.lang.NumberFormatException.forInputString(NumberFormatException.java:65)
	at java.lang.Integer.parseInt(Integer.java:580)
	at java.lang.Integer.parseInt(Integer.java:615)
	at com.example.ExceptionTest.main(MyClass.java:4)  

Integer.parseInt将参数转换为一个整数，并输出这个整数。参数是可能是用户输入的，我们没有办法强制用户输入什么，如果用户输的是数字，比如123，屏幕会输出123，但如果用户输的不是数字，则会出现上面的那个错误。   
根据错误信息的提示，我们来到
```java
// Integer.javad 的第580行：
throw NumberFormatException.forInputString(var0);

// NumberFormatException.java
static NumberFormatException forInputString(String var0) {
    return new NumberFormatException("For input string: \"" + var0 + "\"");
}
```
new NumberFormatException(...)是我们容易理解的，就是创建了一个类的对象，只是这个类是一个异常类。  
throw是什么意思呢？就是抛出异常，它会触发Java的异常处理机制。在之前的空指针异常中，我们没有看到throw的代码，可以认为throw是由Java虚拟机自己实现的。

### throw关键字
throw关键字可以与return关键字进行对比，return代表正常退出，throw代表异常退出，return的返回位置是确定的，就是上一级调用者，而throw后执行哪行代码则经常是不确定的，由异常处理机制动态确定。  

异常处理机制会从当前函数开始查找看谁"捕获"了这个异常，当前函数没有就查看上一层，直到主函数，如果主函数也没有，就使用默认机制，即输出异常栈信息并退出，这正是我们在屏幕输出中看到的。  

### 捕获  
对于屏幕输出中的异常栈信息，程序员是可以理解的，但普通用户无法理解，也不知道该怎么办，我们需要给用户一个更为友好的信息，告诉用户，他应该输入的是数字，要做到这一点，我们需要自己"捕获"异常。   
"捕获"是指使用try/catch关键字，我们看捕获异常后的示例代码：  
```java
package com.example;
public class ExceptionTest {
  public static void main(String[] arg)  {
    try {
          int result= Integer.parseInt("ab3");
          System.out.println("result == " + result);
      } catch (NumberFormatException e) {
          System.out.println("参数不是有效的数字");
      }
  }
}
```
我们使用try/catch捕获并处理了异常，try后面的大括号{}内包含可能抛出异常的代码，括号后的catch语句包含能捕获的异常和处理代码，catch后面括号内是异常信息，包括异常类型和变量名，这里是NumberFormatException e，通过它可以获取更多异常信息，大括号{}内是处理代码，这里输出了一个更为友好的提示信息。

捕获异常后，程序就不会异常退出了，但try语句内异常点之后的其他代码就不会执行了，执行完catch内的语句后，程序会继续执行catch大括号外的代码。

这样，我们就对异常有了一个初步的了解，异常是相对于return的一种退出机制，可以由系统触发，也可以由程序通过throw语句触发，异常可以通过try/catch语句进行捕获并处理，如果没有捕获，则会导致程序退出并输出异常栈信息  

## 了解异常类
### Throwable
NullPointerException和NumberFormatException都是异常类，所有异常类都有一个共同的父类Throwable，它有4个public构造方法：
1. public Throwable()  
2. public Throwable(String message)  
3. public Throwable(String message, Throwable cause)  
4. public Throwable(Throwable cause)   
有两个主要参数，一个是message，表示异常消息，另一个是cause，表示触发该异常的其他异常。异常可以形成一个异常链，上层的异常由底层异常触发，cause表示底层异常。

**常用方法：**   
所有构造方法中都有一句重要的函数调用：
>fillInStackTrace();   

它会将异常栈信息保存下来，这是我们能看到异常栈的关键。   
[重载Throwable.fillInStackTrace方法已提高Java性能这样的做法对法？](https://www.zhihu.com/question/21405047)  

>void printStackTrace()

打印异常栈信息到标准错误输出流。

>String getMessage()  
Throwable getCause()

获取设置的异常message和cause

### 异常类体系
